Workbook

Sheet Projects
C1: RD Projects | BN1: 26 | BP1: 27
B2: # | C2: Projects | E2: PM | F2: TASK COMPLETE | G2: Status | I2: Note | J2: Month 2025 - 2026 | BF2: Month 2026 - 2027
B3: 1 | C3: Features | J3: April | N3: May | R3: June | V3: July | Z3: August | AD3: September | AH3: October | AL3: November | AP3: December | AT3: January | AX3: February | BB3: March | BF3: April | BJ3: May | BN3: June | BR3: July | BV3: August | BZ3: September | CD3: October | CH3: November | CL3: December | CP3: January | CT3: February | CX3: March
C4: Adjust | D4: Zan | E4: Mean | F4: 1 | G4: Done
C5: CleverTap | D5: Jack | E5: Mean | F5: 1 | G5: Done
C6: Ecommerce Shopify | D6: Aek | E6: Mean | F6: 1 | G6: Done
C7: AWS Migration | D7: A | E7: Win | F7: 0.3 | G7: In Progress | H7: Timeline | I7: Dev 85%, UAT 0%, Prod 0%
C8: Thana Datamart API (New Datamart) | D8: Zan | E8: Win | F8: 0.8 | G8: In Progress | H8: Timeline | I8: - Token Light Speed (Dev sp21) Lightspeed Token [5P] Create OM API Connect [5P] Integrate new token flow to light speed service and retest send data - [3P] Update mapping light speed enhancement (Dev sp21) - API send to CT (SA est sp21, Dev sp22) | BB8: dev env
C9: Thana City (Out of Scope OM) | D9: Zan, Aek | E9: Win | F9: 0.6 | G9: In Progress | H9: Timeline | I9: - POS transaction API ของ Light Speed - POS Master data (End of Feb TBC) - Shopify webhook and View tables | BE9: sa, dev
C10: Vimi Termination | D10: Zan, Aek | E10: Mean | F10: 0.6 | G10: In Progress | H10: Timeline | I10: https://docs.google.com/spreadsheets/d/1HlvYW4TgA-JaRO8mMb0kbMwip2YzqJ738MSP5CJ1sls/edit?gid=1729294108#gid=1729294108 | BC10: api 13 | BF10: submit app 30/31 Mar , Release 3 April
C11: New Point Engine | D11: Aom, Jack | E11: Mook | F11: 0.15 | G11: In Progress | H11: Timeline
C12: Subscription Short-Distance (Support App, A920) | D12: Aek, Zan | E12: Mean | F12: 1 | G12: Done | I12: RR App and A920 (ไม่ต้องทำแล้ว รอ confirm) | BF12: monitoring 1 - 3 apr
C13: Pay with Point | D13: Aom, Zan | E13: P'Pop | F13: 0.9 | G13: In Progress | H13: Timeline
C14: Turtle Plus member tier upgrade & downgrade | D14: Zan | E14: Mean | F14: 0.1 | G14: In Progress | I14: Upgrade ใช้ solution เดิม(ตอนนี้), Downgrade -> ทำไฟล์ run script
C15: PayPoint (Point Marketplace) integration | D15: Zan, Aek | E15: Mean | F15: 0 | G15: In Progress | I15: Provided spec
C16: SSO Migration | D16: A | E16: Win | F16: 0 | G16: To Do
C17: Cloud Samsung | F17: 0 | G17: In Progress
C18: Review App Handover document | F18: 0 | G18: Done
C19: Unified App | F19: 0 | G19: In Progress
C20: Rcash PLoan | F20: 0 | G20: In Progress
C21: Tech Debt | F21: 0 | G21: In Progress

Sheet Sprint Resource
B1: Total Manhour/Sprint
A2: Sprint | B2: Date | C2: Aek | D2: Aom | E2: Zan | F2: Jack | G2: A | H2: Mai | I2: Mac | J2: Mos | K2: Nim | L2: Arm | O2: Total All | P2: Total Dev | Q2: Stories Point : Dev | R2: Remark
A3: 6 | B3: 25 Aug - 5 Sep | C3: 6.5 | D3: 6.5 | E3: 6.5 | F3: 6.5 | G3: 6.5 | H3: 6.5 | I3: 6.5 | J3: 6.5 | S3: 1 -> 2h -> 7200
B4: day | C4: 7.5 | D4: 7.5 | E4: 7.5 | F4: 8 | G4: 7.5 | H4: 8 | I4: 8 | J4: 7 | R4: มีวันหยุด 0 วัน | S4: 2 -> 4h -> 14400
B5: hour | C5: =C3*C4 -> 48.75 | D5: =D3*D4 -> 48.75 | E5: =E3*E4 -> 48.75 | F5: =F3*F4 -> 52 | G5: =G3*G4 -> 48.75 | H5: =H3*H4 -> 52 | I5: =I3*I4 -> 52 | J5: =J3*J4 -> 45.5 | O5: =SUM(C5:N5) -> 396.5 | R5: Aom 0.5, Zan 0.5, Aek 0.5, A 0.5, Mos 1 | S5: 3 -> 1d -> 28800
A6: 7 | B6: 8 Sep - 19 Sep | C6: 6.5 | D6: 6.5 | E6: 6.5 | F6: 6.5 | G6: 6.5 | H6: 6.5 | I6: 6.5 | J6: 6.5 | K6: 6.5 | S6: 5 -> 2d -> 57600
B7: day | C7: 8 | D7: 7.5 | E7: 8 | F7: 8 | G7: 8 | H7: 8 | I7: 8 | J7: 7.5 | K7: 7 | R7: มีวันหยุด 0 วัน | S7: 8 -> 3d -> 86400
B8: hour | C8: =C6*C7 -> 52 | D8: =D6*D7 -> 48.75 | E8: =E6*E7 -> 52 | F8: =F6*F7 -> 52 | G8: =G6*G7 -> 52 | H8: =H6*H7 -> 52 | I8: =I6*I7 -> 52 | J8: =J6*J7 -> 48.75 | K8: =K6*K7 -> 45.5 | O8: =SUM(C8:N8) -> 455 | R8: Aom 0.5, Mos 0.5, Nim 1
A9: 8 | B9: 22 Sep - 3 Oct | C9: 6.5 | D9: 6.5 | E9: 6.5 | F9: 6.5 | G9: 6.5 | H9: 6.5 | I9: 6.5 | J9: 6.5 | K9: 6.5 | S9: Mos 7.5
B10: day | C10: 7 | D10: 7 | E10: 8 | F10: 7 | G10: 8 | H10: 7 | I10: 8 | J10: 8 | K10: 8 | R10: มีวันหยุด 0 วัน | S10: Nim 5
B11: hour | C11: =C9*C10 -> 45.5 | D11: =D9*D10 -> 45.5 | E11: =E9*E10 -> 52 | F11: =F9*F10 -> 45.5 | G11: =G9*G10 -> 52 | H11: =H9*H10 -> 45.5 | I11: =I9*I10 -> 52 | J11: =J9*J10 -> 52 | K11: =K9*K10 -> 52 | O11: =SUM(C11:N11) -> 442 | R11: Aek 1, Aom 1, Mai 1, Jack 1 | S11: Arm 4
A12: 9 | B12: 6 Oct - 17 Oct | C12: 6.5 | D12: 6.5 | E12: 6.5 | F12: 6.5 | G12: 6.5 | H12: 6.5 | I12: 6.5 | J12: 6.5 | K12: 6.5
B13: day | C13: 4.5 | D13: 7 | E13: 5 | F13: 6 | G13: 7 | H13: 3 | I13: 7 | J13: 6.5 | K13: 7 | R13: มีวันหยุด 1 วัน
B14: hour | C14: =C12*C13 -> 29.25 | D14: =D12*D13 -> 45.5 | E14: =E12*E13 -> 32.5 | F14: =F12*F13 -> 39 | G14: =G12*G13 -> 45.5 | H14: =H12*H13 -> 19.5 | I14: =I12*I13 -> 45.5 | J14: =J12*J13 -> 42.25 | K14: =K12*K13 -> 45.5 | O14: =SUM(C14:N14) -> 344.5 | R14: Aek 2.5, Zan 2, Mai 4, Jack 1, Mos 0.5
B15: point | C15: =FLOOR((C14/8)*3,1) -> 10 | D15: =FLOOR((D14/8)*3,1) -> 17 | E15: =FLOOR((E14/8)*3,1) -> 12 | F15: =FLOOR((F14/8)*3,1) -> 14 | G15: =FLOOR((G14/8)*3,1) -> 17 | H15: =FLOOR((H14/8)*3,1) -> 7 | I15: =FLOOR((I14/8)*3,1) -> 17 | J15: =FLOOR((J14/8)*3,1) -> 15 | K15: =FLOOR((K14/8)*3,1) -> 17
A16: 10 | B16: 20 Oct - 31 Oct | C16: 6.5 | D16: 6.5 | E16: 6.5 | F16: 6.5 | G16: 6.5 | H16: 6.5 | I16: 6.5 | J16: 6.5 | K16: 6.5
B17: day | C17: 6 | D17: 7 | E17: 7 | F17: 5 | G17: 6 | H17: 7 | I17: 7 | J17: 7 | K17: 7 | R17: มีวันหยุด 1 วัน
B18: hour | C18: =C16*C17 -> 39 | D18: =D16*D17 -> 45.5 | E18: =E16*E17 -> 45.5 | F18: =F16*F17 -> 32.5 | G18: =G16*G17 -> 39 | H18: =H16*H17 -> 45.5 | I18: =I16*I17 -> 45.5 | J18: =J16*J17 -> 45.5 | K18: =K16*K17 -> 45.5 | O18: =SUM(C18:N18) -> 383.5 | R18: Aek 1, Jack 2, A 1
B19: point | C19: =FLOOR((C18/8)*3,1) -> 14 | D19: =FLOOR((D18/8)*3,1) -> 17 | E19: =FLOOR((E18/8)*3,1) -> 17 | F19: =FLOOR((F18/8)*3,1) -> 12 | G19: =FLOOR((G18/8)*3,1) -> 14 | H19: =FLOOR((H18/8)*3,1) -> 17 | I19: =FLOOR((I18/8)*3,1) -> 17 | J19: =FLOOR((J18/8)*3,1) -> 17 | K19: =FLOOR((K18/8)*3,1) -> 17
A20: 11 | B20: 3 Nov - 14 Nov | C20: 6.5 | D20: 6.5 | E20: 6.5 | F20: 6.5 | G20: 6.5 | H20: 6.5 | I20: 6.5 | J20: 6.5 | K20: 6.5 | L20: 6.5
B21: day | C21: 7 | D21: 7 | E21: 8 | F21: 7 | G21: 7.5 | H21: 8 | I21: 6 | J21: 6.5 | K21: 7 | L21: 7 | R21: มีวันหยุด 0 วัน
B22: hour | C22: =C20*C21 -> 45.5 | D22: =D20*D21 -> 45.5 | E22: =E20*E21 -> 52 | F22: =F20*F21 -> 45.5 | G22: =G20*G21 -> 48.75 | H22: =H20*H21 -> 52 | I22: =I20*I21 -> 39 | J22: =J20*J21 -> 42.25 | ... L22: =L20*L21 -> 45.5 | O22: =SUM(C22:N22) -> 461.5 | R22: Jack 1, Nim 1, Mac 2, Aek 1, Aom 1, Arm 1, A 0.5, Mos 1.5
B23: point | C23: =FLOOR((C22/8)*3,1) -> 17 | D23: =FLOOR((D22/8)*3,1) -> 17 | E23: =FLOOR((E22/8)*3,1) -> 19 | F23: =FLOOR((F22/8)*3,1) -> 17 | G23: =FLOOR((G22/8)*3,1) -> 18 | H23: =FLOOR((H22/8)*3,1) -> 19 | I23: =FLOOR((I22/8)*3,1) -> 14 | J23: =FLOOR((J22/8)*3,1) -> 15 | ... L23: =FLOOR((L22/8)*3,1) -> 17
A24: 12 | B24: 17 Nov - 28 Nov | C24: 6.5 | D24: 6.5 | E24: 6.5 | F24: 6.5 | G24: 6.5 | H24: 6.5 | I24: 6.5 | J24: 6.5 | K24: 6.5 | L24: 6.5
B25: day | C25: 8 | D25: 6 | E25: 7 | F25: 8 | G25: 7.5 | H25: 8 | I25: 8 | J25: 6 | K25: 8 | L25: 6 | R25: มีวันหยุด 0 วัน
B26: hour | C26: =C24*C25 -> 52 | D26: =D24*D25 -> 39 | E26: =E24*E25 -> 45.5 | F26: =F24*F25 -> 52 | G26: =G24*G25 -> 48.75 | H26: =H24*H25 -> 52 | I26: =I24*I25 -> 52 | J26: =J24*J25 -> 39 | ... L26: =L24*L25 -> 39 | O26: =SUM(C26:N26) -> 471.25 | R26: Zan 1, Aom 2, Mos 2, A 0.5, Arm 2
B27: point | C27: =FLOOR((C26/8)*3,1) -> 19 | D27: =FLOOR((D26/8)*3,1) -> 14 | E27: =FLOOR((E26/8)*3,1) -> 17 | F27: =FLOOR((F26/8)*3,1) -> 19 | G27: =FLOOR((G26/8)*3,1) -> 18 | H27: =FLOOR((H26/8)*3,1) -> 19 | I27: =FLOOR((I26/8)*3,1) -> 19 | J27: =FLOOR((J26/8)*3,1) -> 14 | ... L27: =FLOOR((L26/8)*3,1) -> 14
A28: 13 | B28: 1 Dec - 12 Dec | C28: 6.5 | D28: 6.5 | E28: 6.5 | F28: 6.5 | G28: 6.5 | H28: 6.5 | I28: 6.5 | J28: 6.5 | K28: 6.5 | L28: 6.5
B29: day | C29: 6 | D29: 3 | E29: 7 | F29: 7 | G29: 7 | H29: 5 | I29: 7 | J29: 6.5 | K29: 5 | L29: 7 | R29: มีวันหยุด 1 วัน
B30: hour | C30: =C28*C29 -> 39 | D30: =D28*D29 -> 19.5 | E30: =E28*E29 -> 45.5 | F30: =F28*F29 -> 45.5 | G30: =G28*G29 -> 45.5 | H30: =H28*H29 -> 32.5 | I30: =I28*I29 -> 45.5 | J30: =J28*J29 -> 42.25 | ... L30: =L28*L29 -> 45.5 | O30: =SUM(C30:N30) -> 393.25 | R30: Aom 4, Mai 2, Nim 2, Aek 1, Mos 0.5
C31: =FLOOR((C30/8)*3,1) -> 14 | D31: =FLOOR((D30/8)*3,1) -> 7 | E31: =FLOOR((E30/8)*3,1) -> 17 | F31: =FLOOR((F30/8)*3,1) -> 17 | G31: =FLOOR((G30/8)*3,1) -> 17 | H31: =FLOOR((H30/8)*3,1) -> 12 | I31: =FLOOR((I30/8)*3,1) -> 17 | J31: =FLOOR((J30/8)*3,1) -> 15 | ... L31: =FLOOR((L30/8)*3,1) -> 17
A32: 14 | B32: 15 Dec - 26 Dec | C32: 6.5 | D32: 6.5 | E32: 6.5 | F32: 6.5 | G32: 6.5 | H32: 6.5 | I32: 6.5 | J32: 6.5 | K32: 6.5 | L32: 6.5
B33: day | C33: 6 | D33: 6 | E33: 8 | F33: 7 | G33: 7 | H33: 8 | I33: 8 | J33: 7 | K33: 7 | L33: 7.5 | R33: มีวันหยุด 0 วัน
B34: hour | C34: =C32*C33 -> 39 | D34: =D32*D33 -> 39 | E34: =E32*E33 -> 52 | F34: =F32*F33 -> 45.5 | G34: =G32*G33 -> 45.5 | H34: =H32*H33 -> 52 | I34: =I32*I33 -> 52 | J34: =J32*J33 -> 45.5 | ... L34: =L32*L33 -> 48.75 | O34: =SUM(C34:N34) -> 464.75 | R34: Nim 1, A 1, Aek 2, Aom 2, Jack 1, Arm 0.5, Mos 1
B35: point | C35: =FLOOR((C34/8)*3,1) -> 14 | D35: =FLOOR((D34/8)*3,1) -> 14 | E35: =FLOOR((E34/8)*3,1) -> 19 | F35: =FLOOR((F34/8)*3,1) -> 17 | G35: =FLOOR((G34/8)*3,1) -> 17 | H35: =FLOOR((H34/8)*3,1) -> 19 | I35: =FLOOR((I34/8)*3,1) -> 19 | J35: =FLOOR((J34/8)*3,1) -> 17 | ... L35: =FLOOR((L34/8)*3,1) -> 18
A36: 15 | B36: 29 Dec - 9 Jan | C36: 6.5 | D36: 6.5 | E36: 6.5 | F36: 6.5 | G36: 6.5 | H36: 6.5 | I36: 6.5 | J36: 6.5 | K36: 6.5 | L36: 6.5
B37: day | C37: 2.5 | D37: 5 | E37: 4.5 | F37: 4 | G37: 4.5 | H37: 5 | I37: 6 | J37: 5.5 | K37: 5 | L37: 6 | R37: มีวันหยุด 2 วัน + ลาสิ้นปี-ปีใหม่กันเยอะ
B38: hour | C38: =C36*C37 -> 16.25 | D38: =D36*D37 -> 32.5 | E38: =E36*E37 -> 29.25 | F38: =F36*F37 -> 26 | G38: =G36*G37 -> 29.25 | H38: =H36*H37 -> 32.5 | I38: =I36*I37 -> 39 | J38: =J36*J37 -> 35.75 | ... L38: =L36*L37 -> 39 | O38: =SUM(C38:N38) -> 312 | R38: Jack 2, A 1.5, Aek 3.5, Aom 1, Zan 1.5, Mai 1, Nim 1, Mos 0.5
B39: point | C39: =FLOOR((C38/8)*3,1) -> 6 | D39: =FLOOR((D38/8)*3,1) -> 12 | E39: =FLOOR((E38/8)*3,1) -> 10 | F39: =FLOOR((F38/8)*3,1) -> 9 | G39: =FLOOR((G38/8)*3,1) -> 10 | H39: =FLOOR((H38/8)*3,1) -> 12 | I39: =FLOOR((I38/8)*3,1) -> 14 | J39: =FLOOR((J38/8)*3,1) -> 13 | ... L39: =FLOOR((L38/8)*3,1) -> 14
A40: 16 | B40: 12 Jan - 23 Jan | C40: 6.5 | D40: 6.5 | E40: 6.5 | F40: 6.5 | G40: 6.5 | H40: 6.5 | I40: 6.5 | J40: 6.5 | K40: 6.5 | L40: 6.5
...

Sheet Resource Allocate
A2: Resource Plan – Sprint 19 23 Feb - 6 Mar
A3: ="Capacity รวมทั้งทีม "&SUM(C14:C19)&" SP" -> Capacity รวมทั้งทีม 118.5 SP | B3: =SUM(C14:C19) -> 118.5
A4: Allocation each project (exclude PE) | B4: =SUM(F20,G20,I20,J20, K20) -> #REF!
A5: Allocation PE | B5: =B3-B4 -> #REF!
A6: New Point Engine | B6: =E20 -> #REF! | C6: 3
A7: Vimi Termination | B7: =F20 -> #REF! | C7: 1
A8: Thana | B8: =G20 -> #REF! | C8: 2
A9: Datamart | B9: =I20 -> #REF! | C9: 1
A10: AWS | B10: =J20 -> #REF! | C10: 1
A11: Dev Support | B11: =K20 -> #REF!
A12: Remaining | B12: =C20-D20 -> #REF!
A13: Name | B13: Availability | C13: Capacity | D13: Total Workload | E13: PE (SP) | F13: VIMI (SP) | G13: Thana (SP) | I13: Datamart (SP) | J13: AWS (SP) | K13: Dev Support (SP)
A14: A | B14: 7 | C14: =3*B14 -> 21 | D14: =SUM(E14,F14,G14,I14,J14,K14) -> #REF! | E14: =3*#REF! -> #REF! | F14: =3*#REF! -> #REF! | G14: =3*#REF! -> #REF! | I14: =3*#REF! -> #REF! | J14: =3*#REF! -> #REF! | K14: 2
A15: Mac | B15: 6 | C15: =3*B15 -> 18 | D15: =SUM(E15,F15,G15,I15,J15,K15) -> #REF! | E15: =3*#REF! -> #REF! | F15: =3*#REF! -> #REF! | G15: =3*#REF! -> #REF! | I15: =3*#REF! -> #REF! | J15: =3*#REF! -> #REF! | K15: =3*#REF! -> #REF!
A16: Mai | B16: 6 | C16: =3*B16 -> 18 | D16: =SUM(E16,F16,G16,I16,J16,K16) -> #REF! | E16: =3*#REF! -> #REF! | F16: =3*#REF! -> #REF! | G16: =3*#REF! -> #REF! | I16: =3*#REF! -> #REF! | K16: =3*#REF! -> #REF!
A17: Mos | B17: 7 | C17: =3*B17 -> 21 | D17: =SUM(E17,F17,G17,I17,J17,K17) -> #REF! | E17: =3*#REF! -> #REF! | F17: =3*#REF! -> #REF! | I17: =3*#REF! -> #REF! | K17: =3*#REF! -> #REF!
A18: Nim | B18: 7 | C18: =3*B18 -> 21 | D18: =SUM(E18,F18,G18,I18,J18,K18) -> #REF! | E18: =3*#REF! -> #REF! | F18: =3*#REF! -> #REF! | I18: =3*#REF! -> #REF! | K18: 2
A19: Arm | B19: 6.5 | C19: =3*B19 -> 19.5 | D19: =SUM(E19,F19,G19,I19,J19,K19) -> #REF! | E19: =3*#REF! -> #REF! | F19: =3*#REF! -> #REF! | I19: =3*#REF! -> #REF! | K19: 3
A20: Total | C20: =SUM(C14:C19) -> 118.5 | D20: =SUM(D14:D19) -> #REF! | E20: =3*#REF! -> #REF! | F20: =3*#REF! -> #REF! | G20: =SUM(G14:G19) -> #REF! | I20: =SUM(I14:I19) -> #REF! | J20: =SUM(J14:J19) -> #REF! | K20: =SUM(K14:K19) -> #REF!
A22: Resource Plan – Sprint 20 9 Mar - 20 Mar
A23: ="Capacity รวม "&SUM(C34:C39)&" SP" -> Capacity รวม 130.5 SP | B23: =SUM(C34:C39) -> 130.5
A24: Allocation each project (exclude PE) | B24: =SUM(F40,G40,I40,J40, K40) -> #REF!
A25: Allocation PE | B25: =B23-B24 -> #REF!
A26: New Point Engine | B26: =E40 -> #REF! | C26: 4
A27: Vimi Termination | B27: =F40 -> #REF! | C27: 1
A28: Thana | B28: =G40 -> #REF! | C28: 2
A29: Datamart | B29: =I40 -> #REF! | C29: 0
A30: AWS | B30: =I40 -> #REF! | C30: 0
A31: Dev Support | B31: =K40 -> #REF! | C31: 1
A32: Remaining | B32: =C40-D40 -> #REF!
A33: Name | B33: Availability | C33: Capacity | D33: Total Workload | E33: PE (SP) | F33: VIMI (SP) | G33: Thana (SP) | I33: AWS (SP) | J33: Adhoc (SP) | K33: Dev Support (SP)
A34: A | B34: 7 | C34: =3*B34 -> 21 | D34: =SUM(E34,F34,G34,I34,J34,K34) -> #REF! | E34: =3*#REF! -> #REF! | F34: =3*#REF! -> #REF! | G34: =3*#REF! -> #REF! | I34: =3*#REF! -> #REF! | J34: =3*#REF! -> #REF! | K34: 1
A35: Mac | B35: 7.5 | C35: =3*B35 -> 22.5 | D35: =SUM(E35,F35,G35,I35,J35,K35) -> #REF! | E35: =3*#REF! -> #REF! | F35: =3*#REF! -> #REF! | G35: =3*#REF! -> #REF! | I35: =3*#REF! -> #REF! | K35: =3*#REF! -> #REF!
A36: Mai | B36: 7 | C36: =3*B36 -> 21 | D36: =SUM(E36,F36,G36,I36,J36,K36) -> #REF! | E36: =3*#REF! -> #REF! | F36: =3*#REF! -> #REF! | G36: =3*#REF! -> #REF! | I36: =3*#REF! -> #REF! | K36: =3*#REF! -> #REF!
A37: Mos | B37: 7 | C37: =3*B37 -> 21 | D37: =SUM(E37,F37,G37,I37,J37,K37) -> #REF! | E37: =3*#REF! -> #REF! | F37: =3*#REF! -> #REF! | G37: =3*#REF! -> #REF! | I37: =3*#REF! -> #REF! | K37: =3*#REF! -> #REF!
A38: Nim | B38: 7 | C38: =3*B38 -> 21 | D38: =SUM(E38,F38,G38,I38,J38,K38) -> #REF! | E38: =3*#REF! -> #REF! | F38: =3*#REF! -> #REF! | G38: =3*#REF! -> #REF! | I38: =3*#REF! -> #REF! | K38: =3*#REF! -> #REF!
A39: Arm | B39: 8 | C39: =3*B39 -> 24 | D39: =SUM(E39,F39,G39,I39,J39,K39) -> #REF! | E39: =3*#REF! -> #REF! | F39: =3*#REF! -> #REF! | G39: =3*#REF! -> #REF! | I39: =3*#REF! -> #REF! | K39: =3*#REF! -> #REF!
A40: Total | C40: =SUM(C34:C39) -> 130.5 | D40: =SUM(D34:D39) -> #REF! | E40: =3*#REF! -> #REF! | F40: =3*#REF! -> #REF! | G40: =SUM(G34:G39) -> #REF! | I40: =SUM(I34:I39) -> #REF! | J40: =SUM(J34:J39) -> #REF! | K40: =SUM(K34:K39) -> #REF!
A42: Resource Plan – Sprint 21 23 Mar - 3 Apr | B42: =SUM(B43:B44) -> 226.5
A43: ="Capacity SA รวม "&SUM(C55:C58)&" SP" -> Capacity SA รวม 90 SP | B43: =SUM(C55:C58) -> 90
...

Sheet Billing 2025
A1: Service | B1: Period | C1: Date | D1: Status | E1: Billing | F1: Billing Account | G1: License | H1: Jan | I1: Feb | J1: Mar | K1: Apr | L1: May | M1: Jun | N1: Jul | O1: Aug | P1: Sep | Q1: Oct | R1: Nov | S1: Dec | T1: Jan | U1: Feb | V1: Mar
A2: Miro | B2: Yearly | C2: 46291 | D2: Active | E2: Link | F2: Aek | G2: 5 Accounts | H2: - | I2: - | J2: - | K2: - | L2: - | M2: 60.99 | N2: - | O2: - | P2: 960 | Q2: 182.61 | R2: - | S2: - | T2: - | U2: - | V2: -
A3: Mailchimp | B3: Monthly | C3: 12 | D3: Active | E3: Link | F3: P'Tong, Aek, P'Su | G3: 41 blocks | H3: 520 | I3: 560 | J3: 620 | K3: 620 | L3: 700 | M3: 780 | N3: 896 | O3: 676 | P3: 676 | Q3: 676 | R3: 676 | S3: 676 | T3: 676 | U3: 676 | V3: 676
A4: Github | B4: Monthly | C4: 21 | D4: Active | E4: Link | F4: Aek, A, Pui, Neung, P'Su | H4: 150.99 | I4: 131.18 | J4: 120.39 | K4: 96.09 | L4: 149.76 | M4: 105.12 | N4: 103.78 | O4: 110.78 | P4: 97.66 | Q4: 129.79 | R4: 125.91 | S4: 123.63 | T4: 119.64 | U4: 139.68 | V4: 151.29
A5: Atlassian (Jira) | B5: Monthly | C5: 10 | D5: Active | E5: Link | F5: P'Tong, Aek, A, P'Su | H5: 424.4 | I5: 414.8 | J5: 414.8 | K5: 391.4 | L5: 408.4 | M5: 440.06 | N5: 906.36 | O5: 1028.84 | P5: 994.25 | Q5: 1006.66 | R5: 1269.14 | S5: 1391.2 | T5: 1435.21 | U5: 1179.92 | V5: 1320.71
A6: Uptime_robot | B6: Yearly | C6: 46283 | D6: Active | F6: Pui, Neung | H6: - | I6: - | J6: - | K6: - | L6: - | M6: - | N6: - | O6: - | P6: 648 | Q6: - | R6: - | S6: - | T6: - | U6: - | V6: -
A7: Bitly | B7: Yearly | C7: 46202 | D7: Active | E7: Link | F7: Aek, A | H7: - | I7: - | J7: - | K7: - | L7: - | M7: 96 | N7: - | O7: - | P7: - | Q7: - | R7: - | S7: - | T7: - | U7: - | V7: -
A8: 101domain.com (rbt.one) | B8: Yearly | C8: 46368 | D8: Active | E8: Link | F8: P'Tong, Aek, A, P'Su | H8: - | I8: - | J8: - | K8: - | L8: - | M8: - | N8: - | O8: - | P8: - | Q8: 38.19 | R8: - | S8: - | T8: - | U8: - | V8: -
A9: Cypress | B9: Yearly | C9: 46082 | D9: Cancelled | F9: Aek, A | H9: - | I9: - | J9: 799 | K9: - | L9: - | M9: - | N9: - | O9: - | P9: - | Q9: - | R9: - | S9: - | T9: - | U9: - | V9: -
A10: Smartsheet | B10: Monthly | C10: 4 | D10: Cancelled | F10: P'Hym | G10: - | H10: 27 | I10: 27 | J10: 36 | K10: 36 | L10: 36 | M10: 36 | N10: 36 | O10: 36 | P10: 36 | Q10: 36 | R10: 36 | S10: 36 | T10: - | U10: - | V10: -
A11: LINE OA | B11: Monthly | C11: 1 | D11: Cancelled | F11: P'Hym, Zan | H11: - | I11: - | J11: - | K11: - | L11: - | M11: - | N11: 40 | O11: 40 | P11: - | Q11: - | R11: - | S11: - | T11: - | U11: - | V11: -
A13: Buffer Jira + 50% | H13: =H5*1.5-H5 -> 212.2 | I13: =I5*1.5-I5 -> 207.4 | J13: =J5*1.5-J5 -> 207.4 | K13: =K5*1.5-K5 -> 195.7 | L13: =L5*1.5-L5 -> 204.2 | M13: =M5*1.5-M5 -> 220.03 | N13: =N5*1.5-N5 -> 453.18 | O13: =O5*1.5-O5 -> 514.42 | ... V13: =V5*1.5-V5 -> 660.355
G14: THB | H14: =SUM(H2:H13)*35 -> 46710.65 | I14: =SUM(I2:I13)*35 -> 46913.3 | J14: =SUM(J2:J13)*35 -> 76915.65 | K14: =SUM(K2:K13)*35 -> 46871.65 | L14: =SUM(L2:L13)*35 -> 52442.6 | M14: =SUM(M2:M13)*35 -> 60837 | N14: =SUM(N2:N13)*35 -> 85236.2 | O14: =SUM(O2:O13)*35 -> 84211.4 | ... V14: =SUM(V2:V13)*35 -> 98292.425
A15: JIra Users | K15: 17 | L15: 18 | M15: 24 | N15: 42 | O15: 42 | P15: 39 | Q15: 35 | R15: 40 | S15: 45 | T15: 46 | U15: 41 | V15: 42
A18: Year 2025 | B18: =SUM(K14:V14) -> 1046680.1
A30: GCloud | B30: Monthly | C30: 1 | D30: Active | F30: P'Yo, A | H30: 7567.47 | I30: 7037.99 | J30: 7699.45 | K30: 7753.38 | L30: 9103.31 | M30: 8970.96 | N30: 9092.62 | O30: 13186.36 | P30: 22225.59 | Q30: 10667.12 | R30: 10406.61 | S30: 10888.43 | T30: 11336.8 | U30: 10323.53
A31: GCloud | G31: THB | H31: =H30*35 -> 264861.45 | I31: =I30*35 -> 246329.65 | J31: =J30*35 -> 269480.75 | K31: =K30*35 -> 271368.3 | L31: =L30*35 -> 318615.85 | M31: =M30*35 -> 313983.6 | N31: =N30*35 -> 318241.7 | O31: =O30*35 -> 461522.6 | ... U31: =U30*35 -> 361323.55

Sheet Forecast Billing 2026
A1: Service | B1: Period | C1: Date | D1: Status | E1: Billing Account | F1: License | G1: Apr | H1: May | I1: Jun | J1: Jul | K1: Aug | L1: Sep | M1: Oct | N1: Nov | O1: Dec | P1: Jan | Q1: Feb | R1: Mar
A2: Miro | B2: Yearly | C2: 46291 | D2: Active | E2: Aek | F2: 5 Accounts | G2: - | H2: - | I2: 60.99 | J2: - | K2: - | L2: 960 | M2: 182.61 | N2: - | O2: - | P2: - | Q2: -
A3: Mailchimp | B3: Monthly | C3: 12 | D3: Active | E3: P'Tong, Aek, P'Su | F3: 41 blocks | G3: 676 | H3: 676 | I3: 676 | J3: 676 | K3: 676 | L3: 676 | M3: 676 | N3: 676 | O3: 676 | P3: 676 | Q3: 676 | R3: 676
A4: Github | B4: Monthly | C4: 21 | D4: Active | E4: Aek, A, Pui, Neung | G4: 150 | H4: 150 | I4: 150 | J4: 150 | K4: 150 | L4: 150 | M4: 150 | N4: 150 | O4: 150 | P4: 150 | Q4: 150 | R4: 150
A5: Atlassian | B5: Monthly | C5: 10 | D5: Active | E5: P'Tong, Aek, A, P'Su | F5: 41 users | G5: 1500 | H5: 1500 | I5: 1500 | J5: 1500 | K5: 1500 | L5: 1500 | M5: 1500 | N5: 1500 | O5: 1500 | P5: 1500 | Q5: 1500 | R5: 1500
A6: Uptime_robot | B6: Yearly | C6: 46283 | D6: Active | E6: Pui, Neung | G6: - | H6: - | I6: - | J6: - | K6: - | L6: 648 | M6: - | N6: - | O6: - | P6: - | Q6: - | R6: -
A7: Bitly | B7: Yearly | C7: 46202 | D7: Active | E7: Aek, A | G7: - | H7: - | I7: 96 | J7: - | K7: - | L7: - | M7: - | N7: - | O7: - | P7: - | Q7: - | R7: -
A8: 101domain.com (rbt.one) | B8: Yearly | C8: 46368 | D8: Active | E8: P'Tong, Aek, A, P'Su | G8: - | H8: - | I8: - | J8: - | K8: - | L8: - | M8: 38.19 | N8: - | O8: - | P8: - | Q8: - | R8: -
A9: AIS | B9: Monthly | C9: 23 | D9: Active | E9: 7200 | F9: • 062-308-5741 • 062-308-5731 • 062-308-5725
A10: Cursor AI | B10: Monthly | D10: To Do | F10: 16 | G10: 640 | H10: 640 | I10: 640 | J10: 640 | K10: 640 | L10: 640 | M10: 640 | N10: 640 | O10: 640 | P10: 640 | Q10: 640 | R10: 640
A12: Buffer Jira + 50% | G12: =G5*1.5-G5 -> 750 | H12: =H5*1.5-H5 -> 750 | I12: =I5*1.5-I5 -> 750 | J12: =J5*1.5-J5 -> 750 | K12: =K5*1.5-K5 -> 750 | L12: =L5*1.5-L5 -> 750 | M12: =M5*1.5-M5 -> 750 | N12: =N5*1.5-N5 -> 750 | ... R12: =R5*1.5-R5 -> 750
F13: THB | G13: =SUM(G2:G12)*35 -> 130060 | H13: =SUM(H2:H12)*35 -> 130060 | I13: =SUM(I2:I12)*35 -> 135554.65 | J13: =SUM(J2:J12)*35 -> 130060 | K13: =SUM(K2:K12)*35 -> 130060 | L13: =SUM(L2:L12)*35 -> 186340 | M13: =SUM(M2:M12)*35 -> 137788 | N13: =SUM(N2:N12)*35 -> 130060 | ... R13: =SUM(R2:R12)*35 -> 130060
A14: JIra Users | G14: 50 | H14: 50 | I14: 50 | J14: 50 | K14: 50 | L14: 50 | M14: 50 | N14: 50 | O14: 50 | P14: 50 | Q14: 50 | R14: 50 | T14: 41
A17: Year 2026 | B17: =SUM(G13:R13)+E9 -> 1637422.6
A29: GCloud | B29: Monthly | C29: 1 | D29: Active | E29: P'Yo, A | G29: 7753.38 | H29: 9103.31 | I29: 8970.96 | J29: 9092.62 | K29: 13186.36 | L29: 22225.59 | M29: 10667.12 | N29: 10406.61 | O29: 10888.43 | P29: 11336.8 | Q29: 10323.53
A30: GCloud | F30: THB | G30: =G29*35 -> 271368.3 | H30: =H29*35 -> 318615.85 | I30: =I29*35 -> 313983.6 | J30: =J29*35 -> 318241.7 | K30: =K29*35 -> 461522.6 | L30: =L29*35 -> 777895.65 | M30: =M29*35 -> 373349.2 | N30: =N29*35 -> 364231.35 | ... Q30: =Q29*35 -> 361323.55

Sheet Summarize Sprint 26
A1: Column 1 | B1: Total Stories Point | C1: Total Manhour | D1: Point Done | E1: Manhour Done | F1: Note
A2: 18 May - 29 May
A3: Dev Resource Available | B3: 21 | C3: 427
A4: Meeting Planned | F4: Ref
A5: Additional Meeting | F5: Ref
A6: Deployment | C6: 2 | F6: 2 ครั้ง 1. 3 คน 2. 1 คน
A7: Development Sprint Total | B7: =SUM('Sprint 26'!O:O) -> 425 | C7: =ROUND(SUM('Sprint 26'!U:U)/3600,2) -> 472.17 | D7: =SUMIF('Sprint 26'!J:J, "Done", 'Sprint 26'!O:O) -> 121 | E7: =ROUND(SUMIF('Sprint 26'!J:J, "Done", 'Sprint 26'!U:U)/3600,2) -> 136.17
A9: Ad-hoc Mid Sprint | B9: 0 | C9: =IFERROR(__xludf.DUMMYFUNCTION("ROUND(IFERROR(SUM(FILTER('Sprint 26'!U:U, ('Sprint 26'!Q:Q = ""mid-sprint"")))/3600,0),2)"),0.0) -> 0 | D9: =IFERROR(__xludf.DUMMYFUNCTION("IFERROR(SUM(FILTER('Sprint 26'!O:O, (('Sprint 26'!J:J = ""Done"")) * ('Sprint 26'!Q:Q = ""mid-sprint""))),0)"),0.0) -> 0 | E9: =IFERROR(__xludf.DUMMYFUNCTION("ROUND(IFERROR(SUM(FILTER('Sprint 26'!U:U, (('Sprint 26'!J:J = ""Done"")) * ('Sprint 26'!P:P = ""mid-sprint"")))/3600,0),2)"),0.0) -> 0 | F9: 2 tasks
A10: Requirement changes after refinement? | B10: =IFERROR(__xludf.DUMMYFUNCTION("ROUND(IFERROR(SUM(FILTER('Sprint 26'!U:U, ('Sprint 26'!Q:Q = ""change-request"")))/3600,0),2)"),0.0) -> 0 | D10: =IFERROR(__xludf.DUMMYFUNCTION("IFERROR(SUM(FILTER('Sprint 26'!O:O, (('Sprint 26'!J:J = ""Done"")) * ('Sprint 26'!Q:Q = ""change-request""))),0)"),0.0) -> 0 | E10: =IFERROR(__xludf.DUMMYFUNCTION("ROUND(IFERROR(SUM(FILTER('Sprint 26'!U:U, (('Sprint 26'!J:J = ""Done"")) * ('Sprint 26'!Q:Q = ""change-request"")))/3600,0),2)"),0.0) -> 0 | F10: 0 tasks
A12: Aek | B12: =IFERROR(__xludf.DUMMYFUNCTION("IFERROR(SUM(FILTER('Sprint 26'!O:O, ('Sprint 26'!E:E = ""Aek:Atiphat Nanthachitvanich""))),0)"),33.0) -> 33 | C12: =IFERROR(__xludf.DUMMYFUNCTION("ROUND(IFERROR(SUM(FILTER('Sprint 26'!U:U, ('Sprint 26'!E:E = ""Aek:Atiphat Nanthachitvanich"")))/3600,0),2)"),47.5) -> 47.5 | D12: =IFERROR(__xludf.DUMMYFUNCTION("IFERROR(SUM(FILTER('Sprint 26'!O:O, (('Sprint 26'!J:J = ""Done"")) * ('Sprint 26'!E:E = ""Aek:Atiphat Nanthachitvanich""))),0)"),13.0) -> 13 | E12: =IFERROR(__xludf.DUMMYFUNCTION("ROUND(IFERROR(SUM(FILTER('Sprint 26'!U:U, (('Sprint 26'!J:J = ""Done"")) * ('Sprint 26'!E:E = ""Aek:Atiphat Nanthachitvanich"")))/3600,0),2)"),15.5) -> 15.5
A13: A | B13: =IFERROR(__xludf.DUMMYFUNCTION("IFERROR(SUM(FILTER('Sprint 26'!O:O, ('Sprint 26'!E:E = ""A:Phongthorn""))),0)"),83.0) -> 83 | C13: =IFERROR(__xludf.DUMMYFUNCTION("ROUND(IFERROR(SUM(FILTER('Sprint 26'!U:U, ('Sprint 26'!E:E = ""A:Phongthorn"")))/3600,0),2)"),220.0) -> 220 | D13: =IFERROR(__xludf.DUMMYFUNCTION("IFERROR(SUM(FILTER('Sprint 26'!O:O, (('Sprint 26'!J:J = ""Done"")) * ('Sprint 26'!E:E = ""A:Phongthorn""))),0)"),4.0) -> 4 | E13: =IFERROR(__xludf.DUMMYFUNCTION("ROUND(IFERROR(SUM(FILTER('Sprint 26'!U:U, (('Sprint 26'!J:J = ""Done"")) * ('Sprint 26'!E:E = ""A:Phongthorn"")))/3600,0),2)"),8.0) -> 8
A14: Aom | B14: =IFERROR(__xludf.DUMMYFUNCTION("IFERROR(SUM(FILTER('Sprint 26'!O:O, ('Sprint 26'!E:E = ""Aom: Pornsawan Polnyiem""))),0)"),35.0) -> 35 | C14: =IFERROR(__xludf.DUMMYFUNCTION("ROUND(IFERROR(SUM(FILTER('Sprint 26'!U:U, ('Sprint 26'!E:E = ""Aom: Pornsawan Polnyiem"")))/3600,0),2)"),0.67) -> 0.67 | D14: =IFERROR(__xludf.DUMMYFUNCTION("IFERROR(SUM(FILTER('Sprint 26'!O:O, (('Sprint 26'!J:J = ""Done"")) * ('Sprint 26'!E:E = ""Aom: Pornsawan Polnyiem""))),0)"),17.0) -> 17 | E14: =IFERROR(__xludf.DUMMYFUNCTION("ROUND(IFERROR(SUM(FILTER('Sprint 26'!U:U, (('Sprint 26'!J:J = ""Done"")) * ('Sprint 26'!E:E = ""Aom: Pornsawan Polnyiem"")))/3600,0),2)"),0.67) -> 0.67
A15: Zan | B15: =IFERROR(__xludf.DUMMYFUNCTION("IFERROR(SUM(FILTER('Sprint 26'!O:O, ('Sprint 26'!E:E = ""Zan : Isarapong Bulan""))),0)"),17.0) -> 17 | C15: =IFERROR(__xludf.DUMMYFUNCTION("ROUND(IFERROR(SUM(FILTER('Sprint 26'!U:U, ('Sprint 26'!E:E = ""Zan : Isarapong Bulan"")))/3600,0),2)"),0.0) -> 0 | D15: =IFERROR(__xludf.DUMMYFUNCTION("IFERROR(SUM(FILTER('Sprint 26'!O:O, (('Sprint 26'!J:J = ""Done"")) * ('Sprint 26'!E:E = ""Zan : Isarapong Bulan""))),0)"),0.0) -> 0 | E15: =IFERROR(__xludf.DUMMYFUNCTION("ROUND(IFERROR(SUM(FILTER('Sprint 26'!U:U, (('Sprint 26'!J:J = ""Done"")) * ('Sprint 26'!E:E = ""Zan : Isarapong Bulan"")))/3600,0),2)"),0.0) -> 0
A16: Mai | B16: =IFERROR(__xludf.DUMMYFUNCTION("IFERROR(SUM(FILTER('Sprint 26'!O:O, ('Sprint 26'!E:E = ""Mai:Sateta Abvanawong""))),0)"),32.0) -> 32 | C16: =IFERROR(__xludf.DUMMYFUNCTION("ROUND(IFERROR(SUM(FILTER('Sprint 26'!U:U, ('Sprint 26'!E:E = ""Mai:Sateta Abvanawong"")))/3600,0),2)"),52.0) -> 52 | D16: =IFERROR(__xludf.DUMMYFUNCTION("IFERROR(SUM(FILTER('Sprint 26'!O:O, (('Sprint 26'!J:J = ""Done"")) * ('Sprint 26'!E:E = ""Mai:Sateta Abvanawong""))),0)"),11.0) -> 11 | E16: =IFERROR(__xludf.DUMMYFUNCTION("ROUND(IFERROR(SUM(FILTER('Sprint 26'!U:U, (('Sprint 26'!J:J = ""Done"")) * ('Sprint 26'!E:E = ""Mai:Sateta Abvanawong""))),0)/3600,2)"),28.0) -> 28
A17: Mac | B17: =IFERROR(__xludf.DUMMYFUNCTION("IFERROR(SUM(FILTER('Sprint 26'!O:O, ('Sprint 26'!E:E = ""Mac: Jarupong Pawichpongkul""))),0)"),56.0) -> 56 | C17: =IFERROR(__xludf.DUMMYFUNCTION("ROUND(IFERROR(SUM(FILTER('Sprint 26'!U:U, ('Sprint 26'!E:E = ""Mac: Jarupong Pawichpongkul"")))/3600,0),2)"),56.0) -> 56 | D17: =IFERROR(__xludf.DUMMYFUNCTION("IFERROR(SUM(FILTER('Sprint 26'!O:O, (('Sprint 26'!J:J = ""Done"")) * ('Sprint 26'!E:E = ""Mac: Jarupong Pawichpongkul""))),0)"),5.0) -> 5 | E17: =IFERROR(__xludf.DUMMYFUNCTION("ROUND(IFERROR(SUM(FILTER('Sprint 26'!U:U, (('Sprint 26'!J:J = ""Done"")) * ('Sprint 26'!E:E = ""Mac: Jarupong Pawichpongkul"")))/3600,0),2)"),0.0) -> 0
A18: Mos | B18: =IFERROR(__xludf.DUMMYFUNCTION("IFERROR(SUM(FILTER('Sprint 26'!O:O, ('Sprint 26'!E:E = ""Moss : Kittapath Sangvikukit""))),0)"),51.0) -> 51 | C18: =IFERROR(__xludf.DUMMYFUNCTION("ROUND(IFERROR(SUM(FILTER('Sprint 26'!U:U, ('Sprint 26'!E:E = ""Moss : Kittapath Sangvikukit"")))/3600,0),2)"),86.0) -> 86 | D18: =IFERROR(__xludf.DUMMYFUNCTION("IFERROR(SUM(FILTER('Sprint 26'!O:O, (('Sprint 26'!J:J = ""Done"")) * ('Sprint 26'!E:E = ""Moss : Kittapath Sangvikukit""))),0)"),39.0) -> 39 | E18: =IFERROR(__xludf.DUMMYFUNCTION("ROUND(IFERROR(SUM(FILTER('Sprint 26'!U:U, (('Sprint 26'!J:J = ""Done"")) * ('Sprint 26'!E:E = ""Moss : Kittapath Sangvikukit"")))/3600,0),2)"),74.0) -> 74
A19: Jack | B19: =IFERROR(__xludf.DUMMYFUNCTION("IFERROR(SUM(FILTER('Sprint 26'!O:O, ('Sprint 26'!E:E = ""Jack: Warin Kesorn""))),0)"),12.0) -> 12 | C19: =IFERROR(__xludf.DUMMYFUNCTION("ROUND(IFERROR(SUM(FILTER('Sprint 26'!U:U, ('Sprint 26'!E:E = ""Jack: Warin Kesorn"")))/3600,0),2)"),0.0) -> 0 | D19: =IFERROR(__xludf.DUMMYFUNCTION("IFERROR(SUM(FILTER('Sprint 26'!O:O, (('Sprint 26'!J:J = ""Done"")) * ('Sprint 26'!E:E = ""Jack: Warin Kesorn""))),0)"),9.0) -> 9 | E19: =IFERROR(__xludf.DUMMYFUNCTION("ROUND(IFERROR(SUM(FILTER('Sprint 26'!U:U, (('Sprint 26'!J:J = ""Done"")) * ('Sprint 26'!E:E = ""Jack: Warin Kesorn"")))/3600,0),2)"),0.0) -> 0
A20: Nim | B20: =IFERROR(__xludf.DUMMYFUNCTION("IFERROR(SUM(FILTER('Sprint 26'!O:O, ('Sprint 26'!E:E = ""Nim : muthita munmueang""))),0)"),41.0) -> 41 | C20: =IFERROR(__xludf.DUMMYFUNCTION("ROUND(IFERROR(SUM(FILTER('Sprint 26'!U:U, ('Sprint 26'!E:E = ""Nim : muthita munmueang"")))/3600,0),2)"),8.0) -> 8 | D20: =IFERROR(__xludf.DUMMYFUNCTION("IFERROR(SUM(FILTER('Sprint 26'!O:O, (('Sprint 26'!J:J = ""Done"")) * ('Sprint 26'!E:E = ""Nim : muthita munmueang""))),0)"),12.0) -> 12 | E20: =IFERROR(__xludf.DUMMYFUNCTION("ROUND(IFERROR(SUM(FILTER('Sprint 26'!U:U, (('Sprint 26'!J:J = ""Done"")) * ('Sprint 26'!E:E = ""Nim : muthita munmueang"")))/3600,0),2)"),8.0) -> 8
A21: Arm | B21: =IFERROR(__xludf.DUMMYFUNCTION("IFERROR(SUM(FILTER('Sprint 26'!O:O, ('Sprint 26'!E:E = ""Arm:Worawat Chotipongchoawalit""))),0)"),64.0) -> 64 | C21: =IFERROR(__xludf.DUMMYFUNCTION("ROUND(IFERROR(SUM(FILTER('Sprint 26'!U:U, ('Sprint 26'!E:E = ""Arm:Worawat Chotipongchoawalit"")))/3600,0),2)"),0.0) -> 0 | D21: =IFERROR(__xludf.DUMMYFUNCTION("IFERROR(SUM(FILTER('Sprint 26'!O:O, (('Sprint 26'!J:J = ""Done"")) * ('Sprint 26'!E:E = ""Arm:Worawat Chotipongchoawalit""))),0)"),10.0) -> 10 | E21: =IFERROR(__xludf.DUMMYFUNCTION("ROUND(IFERROR(SUM(FILTER('Sprint 26'!U:U, (('Sprint 26'!J:J = ""Done"")) * ('Sprint 26'!E:E = ""Arm:Worawat Chotipongchoawalit"")))/3600,0),2)"),0.0) -> 0

Sheet Sprint 26
A1: Issue Type | B1: Issue key | C1: Issue id | D1: Summary | E1: Assignee | F1: Assignee Id | G1: Reporter | H1: Reporter Id | I1: Priority | J1: Status | K1: Resolution | L1: Created | M1: Updated | N1: Due date | O1: Custom field (Story Points) | P1: Labels | Q1: Labels | R1: Labels | S1: Labels | T1: Labels | U1: Original estimate | V1: Sprint | W1: Sprint | X1: Sprint | Y1: Sprint | Z1: Sprint | AA1: Sprint | AB1: Sprint | AC1: Sprint | AD1: Sprint | AE1: Sprint | AF1: Sprint | AG1: Sprint | AH1: Sprint
A2: Sub-task | B2: DPE-700 | C2: 54668 | D2: Test execution | E2: Plai Thanaporn Rimnong-ang | F2: 62c2a5acefb17d6ce62e41bf | G2: Aom: Pornsawan Polnyiem | H2: 5d2ed694a666040c85096e17 | I2: Medium | J2: To Do | L2: 12/Jun/26 4:33 PM | M2: 12/Jun/26 4:33 PM | V2: [Dev][RD][New PE] Sprint 24 | W2: [Dev][RD][New PE] Sprint 25 | X2: [Dev][RD][New PE] Sprint 26
A3: Sub-task | B3: DPE-699 | C3: 54667 | D3: Create test case | E3: Plai Thanaporn Rimnong-ang | F3: 62c2a5acefb17d6ce62e41bf | G3: Aom: Pornsawan Polnyiem | H3: 5d2ed694a666040c85096e17 | I3: Medium | J3: To Do | L3: 12/Jun/26 4:33 PM | M3: 12/Jun/26 4:33 PM | V3: [Dev][RD][New PE] Sprint 24 | W3: [Dev][RD][New PE] Sprint 25 | X3: [Dev][RD][New PE] Sprint 26
A4: Sub-task | B4: DPE-698 | C4: 54666 | D4: Test execution | E4: Plai Thanaporn Rimnong-ang | F4: 62c2a5acefb17d6ce62e41bf | G4: Aom: Pornsawan Polnyiem | H4: 5d2ed694a666040c85096e17 | I4: Medium | J4: To Do | L4: 12/Jun/26 4:33 PM | M4: 12/Jun/26 4:33 PM | V4: [Dev][RD][New PE] Sprint 24 | W4: [Dev][RD][New PE] Sprint 25 | X4: [Dev][RD][New PE] Sprint 26
A5: Sub-task | B5: DPE-697 | C5: 54665 | D5: Create test case | E5: Plai Thanaporn Rimnong-ang | F5: 62c2a5acefb17d6ce62e41bf | G5: Aom: Pornsawan Polnyiem | H5: 5d2ed694a666040c85096e17 | I5: Medium | J5: To Do | L5: 12/Jun/26 4:33 PM | M5: 12/Jun/26 4:33 PM | V5: [Dev][RD][New PE] Sprint 24 | W5: [Dev][RD][New PE] Sprint 25 | X5: [Dev][RD][New PE] Sprint 26
A6: Sub-task | B6: DPE-696 | C6: 54664 | D6: Test execution | E6: Plai Thanaporn Rimnong-ang | F6: 62c2a5acefb17d6ce62e41bf | G6: Aom: Pornsawan Polnyiem | H6: 5d2ed694a666040c85096e17 | I6: Medium | J6: To Do | L6: 12/Jun/26 4:33 PM | M6: 12/Jun/26 4:33 PM | V6: [Dev][RD][New PE] Sprint 22 | W6: [Dev][RD][New PE] Sprint 23 | X6: [Dev][RD][New PE] Sprint 24 | Y6: [Dev][RD][New PE] Sprint 25 | Z6: [Dev][RD][New PE] Sprint 26
A7: Sub-task | B7: DPE-695 | C7: 54663 | D7: Create test case | E7: Plai Thanaporn Rimnong-ang | F7: 62c2a5acefb17d6ce62e41bf | G7: Aom: Pornsawan Polnyiem | H7: 5d2ed694a666040c85096e17 | I7: Medium | J7: To Do | L7: 12/Jun/26 4:33 PM | M7: 12/Jun/26 4:33 PM | V7: [Dev][RD][New PE] Sprint 22 | W7: [Dev][RD][New PE] Sprint 23 | X7: [Dev][RD][New PE] Sprint 24 | Y7: [Dev][RD][New PE] Sprint 25 | Z7: [Dev][RD][New PE] Sprint 26
A8: Sub-task | B8: DPE-694 | C8: 54662 | D8: Test execution | E8: Plai Thanaporn Rimnong-ang | F8: 62c2a5acefb17d6ce62e41bf | G8: Jack: Warin Kesorn | H8: 61a98e8e744c4d00693281d1 | I8: Medium | J8: Done | L8: 12/Jun/26 4:17 PM | M8: 12/Jun/26 4:18 PM | V8: [Dev][RD][New PE] Sprint 26
A9: Sub-task | B9: DPE-693 | C9: 54661 | D9: Create test case | E9: Plai Thanaporn Rimnong-ang | F9: 62c2a5acefb17d6ce62e41bf | G9: Jack: Warin Kesorn | H9: 61a98e8e744c4d00693281d1 | I9: Medium | J9: Done | L9: 12/Jun/26 4:17 PM | M9: 12/Jun/26 4:18 PM | V9: [Dev][RD][New PE] Sprint 26
A10: Story | B10: DEVRDSUP-638 | C10: 54659 | D10: [SUP-734][Need support] ดึง Point จาก User คืน | E10: Aek:Atiphat Nanthachitvanich | F10: 5d48155f5b8ea70c7e4f1b0f | G10: Abhinaf Singh | H10: 712020:a81c99dd-d5cd-44bd-950a-32f4ff7d56ac | I10: Highest | J10: Done | L10: 12/Jun/26 3:41 PM | M10: 12/Jun/26 4:28 PM | N10: 12/Jun/26 12:00 AM | O10: 1 | P10: hop | Q10: reverseTXN | U10: 1800 | V10: [Dev][All Project] Sprint 26
A11: Story | B11: DPE-692 | C11: 54648 | D11: [Dev][RD][PE Middleware] Enhance Get Offer List - Add Offer Type Filter | E11: Arm:Worawat Chotipongchoawalit | F11: 712020:2195d849-5cdb-4ec8-866f-e82a3528bff7 | G11: Jack: Warin Kesorn | H11: 61a98e8e744c4d00693281d1 | I11: Medium | J11: Done | L11: 12/Jun/26 10:49 AM | M11: 12/Jun/26 4:18 PM | P11: point-engine-proxy | V11: [Dev][RD][New PE] Sprint 26
A12: Bug | B12: DPE-689 | C12: 54599 | D12: [S4][RR BOF] Offer name is updated when update the general details | E12: Arm:Worawat Chotipongchoawalit | F12: 712020:2195d849-5cdb-4ec8-866f-e82a3528bff7 | G12: Plai Thanaporn Rimnong-ang | H12: 62c2a5acefb17d6ce62e41bf | I12: Medium | J12: Closed | L12: 10/Jun/26 5:05 PM | M12: 11/Jun/26 1:34 PM | V12: [Dev][RD][New PE] Sprint 26
A13: Sub-task | B13: DPE-688 | C13: 54595 | D13: Test execution | E13: Plai Thanaporn Rimnong-ang | F13: 62c2a5acefb17d6ce62e41bf | G13: Aom: Pornsawan Polnyiem | H13: 5d2ed694a666040c85096e17 | I13: Medium | J13: Done | L13: 10/Jun/26 4:33 PM | M13: 11/Jun/26 1:34 PM | V13: [Dev][RD][New PE] Sprint 26
A14: Sub-task | B14: DPE-687 | C14: 54594 | D14: Create test case | E14: Plai Thanaporn Rimnong-ang | F14: 62c2a5acefb17d6ce62e41bf | G14: Aom: Pornsawan Polnyiem | H14: 5d2ed694a666040c85096e17 | I14: Medium | J14: Done | L14: 10/Jun/26 4:33 PM | M14: 10/Jun/26 4:48 PM | V14: [Dev][RD][New PE] Sprint 26
A15: Sub-task | B15: DPE-686 | C15: 54582 | D15: [QA] Test execution | E15: Plai Thanaporn Rimnong-ang | F15: 62c2a5acefb17d6ce62e41bf | G15: Plai Thanaporn Rimnong-ang | H15: 62c2a5acefb17d6ce62e41bf | I15: Medium | J15: Done | L15: 10/Jun/26 3:48 PM | M15: 11/Jun/26 2:59 PM | V15: [Dev][RD][New PE] Sprint 22 | W15: [Dev][RD][New PE] Sprint 23 | X15: [Dev][RD][New PE] Sprint 24 | Y15: [Dev][RD][New PE] Sprint 25 | Z15: [Dev][RD][New PE] Sprint 26
A16: Story | B16: RDTHANA-518 | C16: 54577 | D16: [SA][RD][TDM] Prepare access control callback request example | E16: Zan : Isarapong Bulan | F16: 5d4814e9da0c4d0c789a4bb7 | G16: Zan : Isarapong Bulan | H16: 5d4814e9da0c4d0c789a4bb7 | I16: Medium | J16: In Review | L16: 10/Jun/26 1:46 PM | M16: 10/Jun/26 1:47 PM | O16: 1 | V16: [Dev][RD][Thana] Sprint 26
A17: Story | B17: DEVRDSUP-633 | C17: 54566 | D17: [SUP-726][SUB] รบกวนออกแพ็กเกจ ปรับเป็น PAID(Confirmed) เรียบร้อย // Order ID: 20260608-0004808 | E17: Aom: Pornsawan Polnyiem | F17: 5d2ed694a666040c85096e17 | G17: Thanakrit Chanthaworn | H17: 712020:3fc982cb-c268-4f1d-9265-d3dd8fb08304 | I17: Medium | J17: Done | L17: 09/Jun/26 6:03 PM | M17: 12/Jun/26 2:00 PM | N17: 12/Jun/26 12:00 AM | O17: 1 | P17: bts | Q17: prod-issue | R17: sub | U17: 600 | V17: [Dev][All Project] Sprint 26
A18: Story | B18: RDAPS-494 | C18: 54557 | D18: [SA][RD] Prepare Callback payload | G18: Zan : Isarapong Bulan | H18: 5d4814e9da0c4d0c789a4bb7 | I18: Medium | J18: To Do | L18: 09/Jun/26 2:52 PM | M18: 09/Jun/26 2:52 PM | V18: [Dev][All Project] Sprint 26
A19: Story | B19: RDAPS-493 | C19: 54556 | D19: [SA][RD] Prepare task sprint #27 - Zan | E19: Zan : Isarapong Bulan | F19: 5d4814e9da0c4d0c789a4bb7 | G19: Zan : Isarapong Bulan | H19: 5d4814e9da0c4d0c789a4bb7 | I19: Medium | J19: In Progress | L19: 09/Jun/26 2:50 PM | M19: 11/Jun/26 9:46 AM | O19: 8 | V19: [Dev][All Project] Sprint 26
A20: Story | B20: DEV-16 | C20: 54555 | D20: [SA][RD][Tech Debt][HRS][DB] Coordinate Staging DB Instance Type Upgrade for Pre-Production Validation | E20: Zan : Isarapong Bulan | F20: 5d4814e9da0c4d0c789a4bb7 | G20: Aek:Atiphat Nanthachitvanich | H20: 5d48155f5b8ea70c7e4f1b0f | I20: Medium | J20: To Do | L20: 09/Jun/26 2:37 PM | M20: 09/Jun/26 3:11 PM | P20: DB | Q20: HRS | R20: Staging | S20: TechDebt | V20: [Dev][RD][TechDebt] Sprint 26
A21: Sub-task | B21: DEV-15 | C21: 54542 | D21: [QA] Test Execution - UAT | E21: Max (QA) : Surawut Sae-nim | F21: 62d4e007098e73c4e5ee0d8d | G21: Max (QA) : Surawut Sae-nim | H21: 62d4e007098e73c4e5ee0d8d | I21: Medium | J21: In Progress | L21: 08/Jun/26 6:11 PM | M21: 08/Jun/26 6:11 PM | V21: [Dev][All Project] Sprint 24 | W21: [Dev][RD][TechDebt] Sprint 25 | X21: [Dev][RD][TechDebt] Sprint 26
A22: Sub-task | B22: DEV-14 | C22: 54540 | D22: [QA] Test Execution - STG | E22: Max (QA) : Surawut Sae-nim | F22: 62d4e007098e73c4e5ee0d8d | G22: Max (QA) : Surawut Sae-nim | H22: 62d4e007098e73c4e5ee0d8d | I22: Medium | J22: Done | L22: 08/Jun/26 6:03 PM | M22: 08/Jun/26 6:10 PM | V22: [Dev][All Project] Sprint 24 | W22: [Dev][RD][TechDebt] Sprint 25 | X22: [Dev][RD][TechDebt] Sprint 26
A23: Sub-task | B23: DPE-680 | C23: 54539 | D23: Test execution | E23: Plai Thanaporn Rimnong-ang | F23: 62c2a5acefb17d6ce62e41bf | G23: Aom: Pornsawan Polnyiem | H23: 5d2ed694a666040c85096e17 | I23: Medium | J23: Done | L23: 08/Jun/26 6:01 PM | M23: 09/Jun/26 4:28 PM | V23: [Dev][RD][New PE] Sprint 24 | W23: [Dev][RD][New PE] Sprint 25 | X23: [Dev][RD][New PE] Sprint 26
A24: Sub-task | B24: DPE-679 | C24: 54538 | D24: Create test case | E24: Plai Thanaporn Rimnong-ang | F24: 62c2a5acefb17d6ce62e41bf | G24: Aom: Pornsawan Polnyiem | H24: 5d2ed694a666040c85096e17 | I24: Medium | J24: Done | L24: 08/Jun/26 6:01 PM | M24: 08/Jun/26 6:01 PM | V24: [Dev][RD][New PE] Sprint 24 | W24: [Dev][RD][New PE] Sprint 25 | X24: [Dev][RD][New PE] Sprint 26
A25: Sub-task | B25: DPE-678 | C25: 54537 | D25: Test execution | E25: Plai Thanaporn Rimnong-ang | F25: 62c2a5acefb17d6ce62e41bf | G25: Aom: Pornsawan Polnyiem | H25: 5d2ed694a666040c85096e17 | I25: Medium | J25: Done | L25: 08/Jun/26 6:01 PM | M25: 09/Jun/26 3:37 PM | V25: [Dev][RD][New PE] Sprint 24 | W25: [Dev][RD][New PE] Sprint 25 | X25: [Dev][RD][New PE] Sprint 26
A26: Sub-task | B26: DPE-677 | C26: 54536 | D26: Create test case | E26: Plai Thanaporn Rimnong-ang | F26: 62c2a5acefb17d6ce62e41bf | G26: Aom: Pornsawan Polnyiem | H26: 5d2ed694a666040c85096e17 | I26: Medium | J26: Done | L26: 08/Jun/26 6:01 PM | M26: 08/Jun/26 6:01 PM | V26: [Dev][RD][New PE] Sprint 24 | W26: [Dev][RD][New PE] Sprint 25 | X26: [Dev][RD][New PE] Sprint 26
A27: Sub-task | B27: DEVRDSUP-631 | C27: 54535 | D27: [QA] Retest - STG | G27: Max (QA) : Surawut Sae-nim | H27: 62d4e007098e73c4e5ee0d8d | I27: Medium | J27: To Do | L27: 08/Jun/26 5:58 PM | M27: 08/Jun/26 6:02 PM | V27: [Dev][All Project] Sprint 24 | W27: [Dev][All Project] Sprint 25 | X27: [Dev][All Project] Sprint 26
A28: Sub-task | B28: DPE-676 | C28: 54534 | D28: Test execution | E28: Plai Thanaporn Rimnong-ang | F28: 62c2a5acefb17d6ce62e41bf | G28: Aom: Pornsawan Polnyiem | H28: 5d2ed694a666040c85096e17 | I28: Medium | J28: Done | L28: 08/Jun/26 5:32 PM | M28: 08/Jun/26 5:32 PM | V28: [Dev][RD][New PE] Sprint 22 | W28: [Dev][RD][New PE] Sprint 23 | X28: [Dev][RD][New PE] Sprint 24 | Y28: [Dev][RD][New PE] Sprint 25 | Z28: [Dev][RD][New PE] Sprint 26
A29: Sub-task | B29: DPE-675 | C29: 54533 | D29: Create test case | E29: Plai Thanaporn Rimnong-ang | F29: 62c2a5acefb17d6ce62e41bf | G29: Aom: Pornsawan Polnyiem | H29: 5d2ed694a666040c85096e17 | I29: Medium | J29: Done | L29: 08/Jun/26 5:32 PM | M29: 08/Jun/26 5:32 PM | V29: [Dev][RD][New PE] Sprint 22 | W29: [Dev][RD][New PE] Sprint 23 | X29: [Dev][RD][New PE] Sprint 24 | Y29: [Dev][RD][New PE] Sprint 25 | Z29: [Dev][RD][New PE] Sprint 26
A30: Story | B30: DEVRDSUP-630 | C30: 54527 | D30: [SUP-722]0880069567996 Line Pay (บัตรใหม่) แต่ระบบหลังบ้านเป็น RC ค่ะ จึงทำให้ลูกค้าไม่สามารถเติมเที่ยวเข้าบัตรได้ | E30: Aek:Atiphat Nanthachitvanich | F30: 5d48155f5b8ea70c7e4f1b0f | G30: Thanakrit Chanthaworn | H30: 712020:3fc982cb-c268-4f1d-9265-d3dd8fb08304 | I30: Medium | J30: Done | L30: 08/Jun/26 5:21 PM | M30: 12/Jun/26 2:00 PM | N30: 11/Jun/26 12:00 AM | O30: 1 | P30: prod-issue | Q30: sub | U30: 1800 | V30: [Dev][All Project] Sprint 26
A31: Story | B31: DEVRDSUP-629 | C31: 54520 | D31: [SUP-721][Access SSO backoffice] Request to create new user N'Nampheung | E31: Aek:Atiphat Nanthachitvanich | F31: 5d48155f5b8ea70c7e4f1b0f | G31: Thanakrit Chanthaworn | H31: 712020:3fc982cb-c268-4f1d-9265-d3dd8fb08304 | I31: Highest | J31: Done | L31: 08/Jun/26 2:35 PM | M31: 12/Jun/26 2:00 PM | N31: 08/Jun/26 12:00 AM | O31: 1 | P31: BURequest | Q31: sso-backoffice | R31: sso-user | U31: 600 | V31: [Dev][All Project] Sprint 26
A32: Story | B32: DEVRDECOM-254 | C32: 54514 | D32: [DEV][RD][Ecom][Gustron][SA] Impact analysis - guest checkout without Rabbit Connect login | E32: Aek:Atiphat Nanthachitvanich | F32: 5d48155f5b8ea70c7e4f1b0f | G32: Aek:Atiphat Nanthachitvanich | H32: 5d48155f5b8ea70c7e4f1b0f | I32: Medium | J32: In Progress | L32: 08/Jun/26 1:16 PM | M32: 12/Jun/26 9:24 AM | O32: 2 | P32: Gustron | Q32: impact-analysis | R32: SA | V32: [Dev][RD][Ecom] Sprint 26
A33: Sub-task | B33: DPE-674 | C33: 54507 | D33: Test execution | E33: Plai Thanaporn Rimnong-ang | F33: 62c2a5acefb17d6ce62e41bf | G33: Aom: Pornsawan Polnyiem | H33: 5d2ed694a666040c85096e17 | I33: Medium | J33: Done | L33: 08/Jun/26 10:49 AM | M33: 08/Jun/26 11:20 AM | V33: [Dev][RD][New PE] Sprint 26
A34: Sub-task | B34: DPE-673 | C34: 54506 | D34: Create test case | E34: Plai Thanaporn Rimnong-ang | F34: 62c2a5acefb17d6ce62e41bf | G34: Aom: Pornsawan Polnyiem | H34: 5d2ed694a666040c85096e17 | I34: Medium | J34: Done | L34: 08/Jun/26 10:49 AM | M34: 08/Jun/26 11:20 AM | V34: [Dev][RD][New PE] Sprint 26
A35: Story | B35: DPE-672 | C35: 54505 | D35: [Dev][RD][PE Proxy Scheduler] Implement Discord notification after each command processed | E35: Arm:Worawat Chotipongchoawalit | F35: 712020:2195d849-5cdb-4ec8-866f-e82a3528bff7 | G35: Aom: Pornsawan Polnyiem | H35: 5d2ed694a666040c85096e17 | I35: Medium | J35: Ready To Test | L35: 08/Jun/26 10:38 AM | M35: 12/Jun/26 10:00 AM | P35: point-engine-proxy-scheduler | V35: [Dev][RD][New PE] Sprint 26
A36: Sub-task | B36: DPE-671 | C36: 54503 | D36: [QA] Test execution | E36: Plai Thanaporn Rimnong-ang | F36: 62c2a5acefb17d6ce62e41bf | G36: Plai Thanaporn Rimnong-ang | H36: 62c2a5acefb17d6ce62e41bf | I36: Medium | J36: Done | L36: 08/Jun/26 9:48 AM | M36: 08/Jun/26 9:49 AM | V36: [Dev][RD][New PE] Sprint 22 | W36: [Dev][RD][New PE] Sprint 23 | X36: [Dev][RD][New PE] Sprint 24 | Y36: [Dev][RD][New PE] Sprint 25 | Z36: [Dev][RD][New PE] Sprint 26
A37: Sub-task | B37: DPE-670 | C37: 54496 | D37: Test execution | E37: Plai Thanaporn Rimnong-ang | F37: 62c2a5acefb17d6ce62e41bf | G37: Aom: Pornsawan Polnyiem | H37: 5d2ed694a666040c85096e17 | I37: Medium | J37: Done | L37: 06/Jun/26 1:31 AM | M37: 08/Jun/26 3:06 PM | V37: [Dev][RD][New PE] Sprint 22 | W37: [Dev][RD][New PE] Sprint 23 | X37: [Dev][RD][New PE] Sprint 24 | Y37: [Dev][RD][New PE] Sprint 25 | Z37: [Dev][RD][New PE] Sprint 26
A38: Sub-task | B38: DPE-669 | C38: 54495 | D38: Create test case | E38: Plai Thanaporn Rimnong-ang | F38: 62c2a5acefb17d6ce62e41bf | G38: Aom: Pornsawan Polnyiem | H38: 5d2ed694a666040c85096e17 | I38: Medium | J38: Done | L38: 06/Jun/26 1:31 AM | M38: 06/Jun/26 1:31 AM | V38: [Dev][RD][New PE] Sprint 22 | W38: [Dev][RD][New PE] Sprint 23 | X38: [Dev][RD][New PE] Sprint 24 | Y38: [Dev][RD][New PE] Sprint 25 | Z38: [Dev][RD][New PE] Sprint 26
A39: Story | B39: DEVRDSUP-627 | C39: 54488 | D39: [SUP-719][Turtle][PL] Request to resend failed point issue TXN to resolve user's complain. The point issue TXN from POS was failed. | E39: Aek:Atiphat Nanthachitvanich | F39: 5d48155f5b8ea70c7e4f1b0f | G39: Abhinaf Singh | H39: 712020:a81c99dd-d5cd-44bd-950a-32f4ff7d56ac | I39: Medium | J39: Done | L39: 05/Jun/26 3:47 PM | M39: 12/Jun/26 2:00 PM | N39: 09/Jun/26 12:00 AM | O39: 1 | P39: partner-loyalty | Q39: turtle | U39: 900 | V39: [Dev][All Project] Sprint 26
A40: Bug | B40: DEVRDSUP-626 | C40: 54483 | D40: [SUP-712]Review of Turtle Coupon Data, missing coupon data on 21&24 May 2026. | E40: Aom: Pornsawan Polnyiem | F40: 5d2ed694a666040c85096e17 | G40: Abhinaf Singh | H40: 712020:a81c99dd-d5cd-44bd-950a-32f4ff7d56ac | I40: Highest | J40: RETESTING | L40: 05/Jun/26 11:39 AM | M40: 12/Jun/26 1:04 PM | N40: 12/Jun/26 12:00 AM | P40: data | Q40: sub | R40: turtle | V40: [Dev][All Project] Sprint 26
...

Sheet Summarize Sprint 25
A1: Column 1 | B1: Total Stories Point | C1: Total Manhour | D1: Point Done | E1: Manhour Done | F1: Note
A2: 18 May - 29 May
A3: Dev Resource Available | B3: 21 | C3: 462
A4: Meeting Planned | F4: Ref
A5: Additional Meeting | F5: Ref
A6: Deployment | C6: 2 | F6: 2 ครั้ง 1. 1 คน 2. 2 คน
A7: Development Sprint Total | B7: =SUM('Sprint 25'!O:O) -> 548 | C7: =ROUND(SUM('Sprint 25'!U:U)/3600,2) -> 804.17 | D7: =SUMIF('Sprint 25'!J:J, "Done", 'Sprint 25'!O:O) -> 300 | E7: =ROUND(SUMIF('Sprint 25'!J:J, "Done", 'Sprint 25'!U:U)/3600,2) -> 448.17
A9: Ad-hoc Mid Sprint | B9: 0 | C9: =IFERROR(__xludf.DUMMYFUNCTION("ROUND(IFERROR(SUM(FILTER('Sprint 25'!U:U, ('Sprint 25'!Q:Q = ""mid-sprint"")))/3600,0),2)"),0.0) -> 0 | D9: =IFERROR(__xludf.DUMMYFUNCTION("IFERROR(SUM(FILTER('Sprint 25'!O:O, (('Sprint 25'!J:J = ""Done"")) * ('Sprint 25'!Q:Q = ""mid-sprint""))),0)"),0.0) -> 0 | E9: =IFERROR(__xludf.DUMMYFUNCTION("ROUND(IFERROR(SUM(FILTER('Sprint 25'!U:U, (('Sprint 25'!J:J = ""Done"")) * ('Sprint 25'!P:P = ""mid-sprint"")))/3600,0),2)"),0.0) -> 0 | F9: 2 tasks
A10: Requirement changes after refinement? | B10: =IFERROR(__xludf.DUMMYFUNCTION("ROUND(IFERROR(SUM(FILTER('Sprint 25'!U:U, ('Sprint 25'!Q:Q = ""change-request"")))/3600,0),2)"),0.0) -> 0 | D10: =IFERROR(__xludf.DUMMYFUNCTION("IFERROR(SUM(FILTER('Sprint 25'!O:O, (('Sprint 25'!J:J = ""Done"")) * ('Sprint 25'!Q:Q = ""change-request""))),0)"),0.0) -> 0 | E10: =IFERROR(__xludf.DUMMYFUNCTION("ROUND(IFERROR(SUM(FILTER('Sprint 25'!U:U, (('Sprint 25'!J:J = ""Done"")) * ('Sprint 25'!Q:Q = ""change-request"")))/3600,0),2)"),0.0) -> 0 | F10: 0 tasks
A12: Aek | B12: =IFERROR(__xludf.DUMMYFUNCTION("IFERROR(SUM(FILTER('Sprint 25'!O:O, ('Sprint 25'!E:E = ""Aek:Atiphat Nanthachitvanich""))),0)"),35.0) -> 35 | C12: =IFERROR(__xludf.DUMMYFUNCTION("ROUND(IFERROR(SUM(FILTER('Sprint 25'!U:U, ('Sprint 25'!E:E = ""Aek:Atiphat Nanthachitvanich"")))/3600,0),2)"),91.0) -> 91 | D12: =IFERROR(__xludf.DUMMYFUNCTION("IFERROR(SUM(FILTER('Sprint 25'!O:O, (('Sprint 25'!J:J = ""Done"")) * ('Sprint 25'!E:E = ""Aek:Atiphat Nanthachitvanich""))),0)"),27.0) -> 27 | E12: =IFERROR(__xludf.DUMMYFUNCTION("ROUND(IFERROR(SUM(FILTER('Sprint 25'!U:U, (('Sprint 25'!J:J = ""Done"")) * ('Sprint 25'!E:E = ""Aek:Atiphat Nanthachitvanich"")))/3600,0),2)"),59.0) -> 59
A13: A | B13: =IFERROR(__xludf.DUMMYFUNCTION("IFERROR(SUM(FILTER('Sprint 25'!O:O, ('Sprint 25'!E:E = ""A:Phongthorn""))),0)"),89.0) -> 89 | C13: =IFERROR(__xludf.DUMMYFUNCTION("ROUND(IFERROR(SUM(FILTER('Sprint 25'!U:U, ('Sprint 25'!E:E = ""A:Phongthorn"")))/3600,0),2)"),230.0) -> 230 | D13: =IFERROR(__xludf.DUMMYFUNCTION("IFERROR(SUM(FILTER('Sprint 25'!O:O, (('Sprint 25'!J:J = ""Done"")) * ('Sprint 25'!E:E = ""A:Phongthorn""))),0)"),27.0) -> 27 | E13: =IFERROR(__xludf.DUMMYFUNCTION("ROUND(IFERROR(SUM(FILTER('Sprint 25'!U:U, (('Sprint 25'!J:J = ""Done"")) * ('Sprint 25'!E:E = ""A:Phongthorn"")))/3600,0),2)"),68.0) -> 68
A14: Aom | B14: =IFERROR(__xludf.DUMMYFUNCTION("IFERROR(SUM(FILTER('Sprint 25'!O:O, ('Sprint 25'!E:E = ""Aom: Pornsawan Polnyiem""))),0)"),47.0) -> 47 | C14: =IFERROR(__xludf.DUMMYFUNCTION("ROUND(IFERROR(SUM(FILTER('Sprint 25'!U:U, ('Sprint 25'!E:E = ""Aom: Pornsawan Polnyiem"")))/3600,0),2)"),0.17) -> 0.17 | D14: =IFERROR(__xludf.DUMMYFUNCTION("IFERROR(SUM(FILTER('Sprint 25'!O:O, (('Sprint 25'!J:J = ""Done"")) * ('Sprint 25'!E:E = ""Aom: Pornsawan Polnyiem""))),0)"),43.0) -> 43 | E14: =IFERROR(__xludf.DUMMYFUNCTION("ROUND(IFERROR(SUM(FILTER('Sprint 25'!U:U, (('Sprint 25'!J:J = ""Done"")) * ('Sprint 25'!E:E = ""Aom: Pornsawan Polnyiem"")))/3600,0),2)"),0.17) -> 0.17
A15: Zan | B15: =IFERROR(__xludf.DUMMYFUNCTION("IFERROR(SUM(FILTER('Sprint 25'!O:O, ('Sprint 25'!E:E = ""Zan : Isarapong Bulan""))),0)"),9.0) -> 9 | C15: =IFERROR(__xludf.DUMMYFUNCTION("ROUND(IFERROR(SUM(FILTER('Sprint 25'!U:U, ('Sprint 25'!E:E = ""Zan : Isarapong Bulan"")))/3600,0),2)"),0.0) -> 0 | D15: =IFERROR(__xludf.DUMMYFUNCTION("IFERROR(SUM(FILTER('Sprint 25'!O:O, (('Sprint 25'!J:J = ""Done"")) * ('Sprint 25'!E:E = ""Zan : Isarapong Bulan""))),0)"),1.0) -> 1 | E15: =IFERROR(__xludf.DUMMYFUNCTION("ROUND(IFERROR(SUM(FILTER('Sprint 25'!U:U, (('Sprint 25'!J:J = ""Done"")) * ('Sprint 25'!E:E = ""Zan : Isarapong Bulan"")))/3600,0),2)"),0.0) -> 0
A16: Mai | B16: =IFERROR(__xludf.DUMMYFUNCTION("IFERROR(SUM(FILTER('Sprint 25'!O:O, ('Sprint 25'!E:E = ""Mai:Sateta Abvanawong""))),0)"),73.0) -> 73 | C16: =IFERROR(__xludf.DUMMYFUNCTION("ROUND(IFERROR(SUM(FILTER('Sprint 25'!U:U, ('Sprint 25'!E:E = ""Mai:Sateta Abvanawong"")))/3600,0),2)"),146.0) -> 146 | D16: =IFERROR(__xludf.DUMMYFUNCTION("IFERROR(SUM(FILTER('Sprint 25'!O:O, (('Sprint 25'!J:J = ""Done"")) * ('Sprint 25'!E:E = ""Mai:Sateta Abvanawong""))),0)"),55.0) -> 55 | E16: =IFERROR(__xludf.DUMMYFUNCTION("ROUND(IFERROR(SUM(FILTER('Sprint 25'!U:U, (('Sprint 25'!J:J = ""Done"")) * ('Sprint 25'!E:E = ""Mai:Sateta Abvanawong""))),0)/3600,2)"),118.0) -> 118
A17: Mac | B17: =IFERROR(__xludf.DUMMYFUNCTION("IFERROR(SUM(FILTER('Sprint 25'!O:O, ('Sprint 25'!E:E = ""Mac: Jarupong Pawichpongkul""))),0)"),84.0) -> 84 | C17: =IFERROR(__xludf.DUMMYFUNCTION("ROUND(IFERROR(SUM(FILTER('Sprint 25'!U:U, ('Sprint 25'!E:E = ""Mac: Jarupong Pawichpongkul"")))/3600,0),2)"),176.0) -> 176 | D17: =IFERROR(__xludf.DUMMYFUNCTION("IFERROR(SUM(FILTER('Sprint 25'!O:O, (('Sprint 25'!J:J = ""Done"")) * ('Sprint 25'!E:E = ""Mac: Jarupong Pawichpongkul""))),0)"),57.0) -> 57 | E17: =IFERROR(__xludf.DUMMYFUNCTION("ROUND(IFERROR(SUM(FILTER('Sprint 25'!U:U, (('Sprint 25'!J:J = ""Done"")) * ('Sprint 25'!E:E = ""Mac: Jarupong Pawichpongkul"")))/3600,0),2)"),120.0) -> 120
A18: Mos | B18: =IFERROR(__xludf.DUMMYFUNCTION("IFERROR(SUM(FILTER('Sprint 25'!O:O, ('Sprint 25'!E:E = ""Moss : Kittapath Sangvikukit""))),0)"),71.0) -> 71 | C18: =IFERROR(__xludf.DUMMYFUNCTION("ROUND(IFERROR(SUM(FILTER('Sprint 25'!U:U, ('Sprint 25'!E:E = ""Moss : Kittapath Sangvikukit"")))/3600,0),2)"),121.0) -> 121 | D18: =IFERROR(__xludf.DUMMYFUNCTION("IFERROR(SUM(FILTER('Sprint 25'!O:O, (('Sprint 25'!J:J = ""Done"")) * ('Sprint 25'!E:E = ""Moss : Kittapath Sangvikukit""))),0)"),32.0) -> 32 | E18: =IFERROR(__xludf.DUMMYFUNCTION("ROUND(IFERROR(SUM(FILTER('Sprint 25'!U:U, (('Sprint 25'!J:J = ""Done"")) * ('Sprint 25'!E:E = ""Moss : Kittapath Sangvikukit"")))/3600,0),2)"),51.0) -> 51
A19: Jack | B19: =IFERROR(__xludf.DUMMYFUNCTION("IFERROR(SUM(FILTER('Sprint 25'!O:O, ('Sprint 25'!E:E = ""Jack: Warin Kesorn""))),0)"),5.0) -> 5 | C19: =IFERROR(__xludf.DUMMYFUNCTION("ROUND(IFERROR(SUM(FILTER('Sprint 25'!U:U, ('Sprint 25'!E:E = ""Jack: Warin Kesorn"")))/3600,0),2)"),0.0) -> 0 | D19: =IFERROR(__xludf.DUMMYFUNCTION("IFERROR(SUM(FILTER('Sprint 25'!O:O, (('Sprint 25'!J:J = ""Done"")) * ('Sprint 25'!E:E = ""Jack: Warin Kesorn""))),0)"),5.0) -> 5 | E19: =IFERROR(__xludf.DUMMYFUNCTION("ROUND(IFERROR(SUM(FILTER('Sprint 25'!U:U, (('Sprint 25'!J:J = ""Done"")) * ('Sprint 25'!E:E = ""Jack: Warin Kesorn"")))/3600,0),2)"),0.0) -> 0
A20: Nim | B20: =IFERROR(__xludf.DUMMYFUNCTION("IFERROR(SUM(FILTER('Sprint 25'!O:O, ('Sprint 25'!E:E = ""Nim : muthita munmueang""))),0)"),64.0) -> 64 | C20: =IFERROR(__xludf.DUMMYFUNCTION("ROUND(IFERROR(SUM(FILTER('Sprint 25'!U:U, ('Sprint 25'!E:E = ""Nim : muthita munmueang"")))/3600,0),2)"),40.0) -> 40 | D20: =IFERROR(__xludf.DUMMYFUNCTION("IFERROR(SUM(FILTER('Sprint 25'!O:O, (('Sprint 25'!J:J = ""Done"")) * ('Sprint 25'!E:E = ""Nim : muthita munmueang""))),0)"),39.0) -> 39 | E20: =IFERROR(__xludf.DUMMYFUNCTION("ROUND(IFERROR(SUM(FILTER('Sprint 25'!U:U, (('Sprint 25'!J:J = ""Done"")) * ('Sprint 25'!E:E = ""Nim : muthita munmueang"")))/3600,0),2)"),32.0) -> 32
A21: Arm | B21: =IFERROR(__xludf.DUMMYFUNCTION("IFERROR(SUM(FILTER('Sprint 25'!O:O, ('Sprint 25'!E:E = ""Arm:Worawat Chotipongchoawalit""))),0)"),71.0) -> 71 | C21: =IFERROR(__xludf.DUMMYFUNCTION("ROUND(IFERROR(SUM(FILTER('Sprint 25'!U:U, ('Sprint 25'!E:E = ""Arm:Worawat Chotipongchoawalit"")))/3600,0),2)"),0.0) -> 0 | D21: =IFERROR(__xludf.DUMMYFUNCTION("IFERROR(SUM(FILTER('Sprint 25'!O:O, (('Sprint 25'!J:J = ""Done"")) * ('Sprint 25'!E:E = ""Arm:Worawat Chotipongchoawalit""))),0)"),14.0) -> 14 | E21: =IFERROR(__xludf.DUMMYFUNCTION("ROUND(IFERROR(SUM(FILTER('Sprint 25'!U:U, (('Sprint 25'!J:J = ""Done"")) * ('Sprint 25'!E:E = ""Arm:Worawat Chotipongchoawalit"")))/3600,0),2)"),0.0) -> 0

Sheet Sprint 25
A1: Issue Type | B1: Issue key | C1: Issue id | D1: Summary | E1: Assignee | F1: Assignee Id | G1: Reporter | H1: Reporter Id | I1: Priority | J1: Status | K1: Resolution | L1: Created | M1: Updated | N1: Due date | O1: Custom field (Story Points) | P1: Labels | Q1: Labels | R1: Labels | S1: Labels | T1: Labels | U1: Original estimate | V1: Sprint | W1: Sprint | X1: Sprint | Y1: Sprint | Z1: Sprint | AA1: Sprint | AB1: Sprint | AC1: Sprint | AD1: Sprint | AE1: Sprint | AF1: Sprint | AG1: Sprint | AH1: Sprint
A2: Sub-task | B2: RDAPS-492 | C2: 54443 | D2: [QA] Test Execution Verify Enhance clear member card cache after add card success | E2: Pueng Prachpreeya | F2: 642a5328f8bc2116accac530 | G2: Pueng Prachpreeya | H2: 642a5328f8bc2116accac530 | I2: Medium | J2: Done | L2: 02/Jun/26 2:53 PM | M2: 02/Jun/26 5:30 PM | V2: [Dev][All Project] Sprint 25 | W2: [Dev][All Project] Sprint 26
A3: Sub-task | B3: DPE-660 | C3: 54440 | D3: Test execution | E3: Plai Thanaporn Rimnong-ang | F3: 62c2a5acefb17d6ce62e41bf | G3: Aom: Pornsawan Polnyiem | H3: 5d2ed694a666040c85096e17 | I3: Medium | J3: To Do | L3: 02/Jun/26 1:57 PM | M3: 02/Jun/26 1:57 PM | V3: [Dev][RD][New PE] Sprint 21 | W3: [Dev][RD][New PE] Sprint 22 | X3: [Dev][RD][New PE] Sprint 23 | Y3: [Dev][RD][New PE] Sprint 24 | Z3: [Dev][RD][New PE] Sprint 25 | AA3: [Dev][RD][New PE] Sprint 26
A4: Sub-task | B4: DPE-659 | C4: 54439 | D4: Create test case | E4: Plai Thanaporn Rimnong-ang | F4: 62c2a5acefb17d6ce62e41bf | G4: Aom: Pornsawan Polnyiem | H4: 5d2ed694a666040c85096e17 | I4: Medium | J4: In Progress | L4: 02/Jun/26 1:57 PM | M4: 02/Jun/26 2:11 PM | V4: [Dev][RD][New PE] Sprint 21 | W4: [Dev][RD][New PE] Sprint 22 | X4: [Dev][RD][New PE] Sprint 23 | Y4: [Dev][RD][New PE] Sprint 24 | Z4: [Dev][RD][New PE] Sprint 25 | AA4: [Dev][RD][New PE] Sprint 26
A5: Sub-task | B5: DPE-658 | C5: 54411 | D5: Test execution | E5: Plai Thanaporn Rimnong-ang | F5: 62c2a5acefb17d6ce62e41bf | G5: Aom: Pornsawan Polnyiem | H5: 5d2ed694a666040c85096e17 | I5: Medium | J5: To Do | L5: 01/Jun/26 5:38 PM | M5: 01/Jun/26 5:39 PM | V5: [Dev][RD][New PE] Sprint 21 | W5: [Dev][RD][New PE] Sprint 22 | X5: [Dev][RD][New PE] Sprint 23 | Y5: [Dev][RD][New PE] Sprint 24 | Z5: [Dev][RD][New PE] Sprint 25 | AA5: [Dev][RD][New PE] Sprint 26
A6: Sub-task | B6: DPE-657 | C6: 54410 | D6: Create test case | E6: Plai Thanaporn Rimnong-ang | F6: 62c2a5acefb17d6ce62e41bf | G6: Aom: Pornsawan Polnyiem | H6: 5d2ed694a666040c85096e17 | I6: Medium | J6: In Progress | L6: 01/Jun/26 5:38 PM | M6: 02/Jun/26 2:11 PM | V6: [Dev][RD][New PE] Sprint 21 | W6: [Dev][RD][New PE] Sprint 22 | X6: [Dev][RD][New PE] Sprint 23 | Y6: [Dev][RD][New PE] Sprint 24 | Z6: [Dev][RD][New PE] Sprint 25 | AA6: [Dev][RD][New PE] Sprint 26
A7: Sub-task | B7: DPE-656 | C7: 54409 | D7: Test execution | E7: Plai Thanaporn Rimnong-ang | F7: 62c2a5acefb17d6ce62e41bf | G7: Aom: Pornsawan Polnyiem | H7: 5d2ed694a666040c85096e17 | I7: Medium | J7: To Do | L7: 01/Jun/26 5:38 PM | M7: 01/Jun/26 5:38 PM | V7: [Dev][RD][New PE] Sprint 24 | W7: [Dev][RD][New PE] Sprint 25 | X7: [Dev][RD][New PE] Sprint 26
A8: Sub-task | B8: DPE-655 | C8: 54408 | D8: Test execution | E8: Plai Thanaporn Rimnong-ang | F8: 62c2a5acefb17d6ce62e41bf | G8: Aom: Pornsawan Polnyiem | H8: 5d2ed694a666040c85096e17 | I8: Medium | J8: To Do | L8: 01/Jun/26 5:38 PM | M8: 01/Jun/26 5:38 PM | V8: [Dev][RD][New PE] Sprint 24 | W8: [Dev][RD][New PE] Sprint 25 | X8: [Dev][RD][New PE] Sprint 26
A9: Sub-task | B9: DPE-654 | C9: 54407 | D9: Create test case | E9: Plai Thanaporn Rimnong-ang | F9: 62c2a5acefb17d6ce62e41bf | G9: Aom: Pornsawan Polnyiem | H9: 5d2ed694a666040c85096e17 | I9: Medium | J9: In Progress | L9: 01/Jun/26 5:38 PM | M9: 02/Jun/26 2:11 PM | V9: [Dev][RD][New PE] Sprint 24 | W9: [Dev][RD][New PE] Sprint 25 | X9: [Dev][RD][New PE] Sprint 26
A10: Sub-task | B10: DPE-653 | C10: 54406 | D10: Create test case | E10: Plai Thanaporn Rimnong-ang | F10: 62c2a5acefb17d6ce62e41bf | G10: Aom: Pornsawan Polnyiem | H10: 5d2ed694a666040c85096e17 | I10: Medium | J10: In Progress | L10: 01/Jun/26 5:38 PM | M10: 02/Jun/26 2:11 PM | V10: [Dev][RD][New PE] Sprint 24 | W10: [Dev][RD][New PE] Sprint 25 | X10: [Dev][RD][New PE] Sprint 26
A11: Sub-task | B11: DPE-652 | C11: 54405 | D11: Test execution | E11: Plai Thanaporn Rimnong-ang | F11: 62c2a5acefb17d6ce62e41bf | G11: Aom: Pornsawan Polnyiem | H11: 5d2ed694a666040c85096e17 | I11: Medium | J11: To Do | L11: 01/Jun/26 5:38 PM | M11: 01/Jun/26 5:38 PM | V11: [Dev][RD][New PE] Sprint 24 | W11: [Dev][RD][New PE] Sprint 25 | X11: [Dev][RD][New PE] Sprint 26
A12: Sub-task | B12: DPE-651 | C12: 54404 | D12: Create test case | E12: Plai Thanaporn Rimnong-ang | F12: 62c2a5acefb17d6ce62e41bf | G12: Aom: Pornsawan Polnyiem | H12: 5d2ed694a666040c85096e17 | I12: Medium | J12: In Progress | L12: 01/Jun/26 5:38 PM | M12: 02/Jun/26 2:11 PM | V12: [Dev][RD][New PE] Sprint 24 | W12: [Dev][RD][New PE] Sprint 25 | X12: [Dev][RD][New PE] Sprint 26
